/raid/home/automathon_2024/account13/.local/lib/python3.10/site-packages/torch/cuda/__init__.py:118: UserWarning: CUDA initialization: CUDA unknown error - this may be due to an incorrectly set up environment, e.g. changing env variable CUDA_VISIBLE_DEVICES after program start. Setting the available devices to be zero. (Triggered internally at ../c10/cuda/CUDAFunctions.cpp:108.)
  return torch._C._cuda_getDeviceCount() > 0
Traceback (most recent call last):
  File "/raid/home/automathon_2024/account13/.local/lib/python3.10/site-packages/torchinfo/torchinfo.py", line 295, in forward_pass
    _ = model(*x, **kwargs)
  File "/raid/home/automathon_2024/account13/.local/lib/python3.10/site-packages/torch/nn/modules/module.py", line 1532, in _wrapped_call_impl
    return self._call_impl(*args, **kwargs)
  File "/raid/home/automathon_2024/account13/.local/lib/python3.10/site-packages/torch/nn/modules/module.py", line 1582, in _call_impl
    result = forward_call(*args, **kwargs)
  File "/raid/home/automathon_2024/account13/anon/automathon-2024/run.py", line 263, in forward
    y = self.dense(y)
  File "/raid/home/automathon_2024/account13/.local/lib/python3.10/site-packages/torch/nn/modules/module.py", line 1532, in _wrapped_call_impl
    return self._call_impl(*args, **kwargs)
  File "/raid/home/automathon_2024/account13/.local/lib/python3.10/site-packages/torch/nn/modules/module.py", line 1582, in _call_impl
    result = forward_call(*args, **kwargs)
  File "/raid/home/automathon_2024/account13/.local/lib/python3.10/site-packages/torch/nn/modules/linear.py", line 116, in forward
    return F.linear(input, self.weight, self.bias)
RuntimeError: mat1 and mat2 shapes cannot be multiplied (32x57600 and 125829120x1)
The above exception was the direct cause of the following exception:
Traceback (most recent call last):
  File "/raid/home/automathon_2024/account13/anon/automathon-2024/run.py", line 283, in <module>
    summary(model, input_size=(batch_size, 3, 10, 256, 256))
  File "/raid/home/automathon_2024/account13/.local/lib/python3.10/site-packages/torchinfo/torchinfo.py", line 223, in summary
    summary_list = forward_pass(
  File "/raid/home/automathon_2024/account13/.local/lib/python3.10/site-packages/torchinfo/torchinfo.py", line 304, in forward_pass
    raise RuntimeError(
RuntimeError: Failed to run torchinfo. See above stack traces for more details. Executed layers up to: [Conv2d: 1, ReLU: 1, MaxPool2d: 1, Conv2d: 1, ReLU: 1, MaxPool2d: 1, Conv2d: 1, ReLU: 1, MaxPool2d: 1, Flatten: 1]
Training model: